Workbook

Sheet Conciliacion semanal
A1: DANCONA ALIMENTOS - CONCILIACIÓN BANCARIA SEMANAL
A2: Banco Nación Argentina - Mendoza
A3: Conciliación al 24/04/2026 (período 20/04/2026 al 24/04/2026; banco con movimientos hasta 24/04/2026)
A5: Concepto | B5: Importe
A6: Saldo S/Extracto Bancario al 24/04/2026 | B6: 29620748
A7: Saldo S/FLEXXUS al 24/04/2026 | B7: 37824484
A8: DIFERENCIA INICIAL (extracto banco vs libro Flexxus) | B8: =B6-B7
A10: Menos: INGRESOS registrados en FLEXXUS que NO están en el Banco | B10: =SUMIF('Flexxus no Banco'!D:D,"PAV",'Flexxus no Banco'!G:G)
A11: Más: EGRESOS registrados en FLEXXUS que NO están en el Banco | B11: =SUM('Flexxus no Banco'!G:G)-B10
A12: Más: INGRESOS en el Banco pero NO registrados en FLEXXUS | B12: =SUM('Banco ingresos no Flexxus'!H:H)
A13: Menos: EGRESOS en el Banco pero NO registrados en FLEXXUS | B13: =SUM('Banco egresos no Flexxus'!I:I)
A14: Pendientes anteriores: incluidos dentro de los bloques anteriores (NO impacta como residual) | B14: =0
A16: SALDO REAL S/FLEXXUS SEGÚN ARCHIVO ACTUAL al 24/04/2026 | B16: =B7
A17: SALDO FLEXXUS AJUSTADO PARA CONCILIACIÓN BANCARIA (= Flex - C1 + C2) | B17: =B7-B10+B11
A18: TOTAL MOVIMIENTOS CONCILIADOS / .XLS A IMPORTAR | B18: ='Carga Flexxus'!C5
A19: SALDO BANCO CALCULADO (= Flex - C1 + C2 + C3 - C4) | B19: =B7-B10+B11+B12-B13
A20: SALDO SEGÚN EXTRACTO BANCO al 24/04/2026 | B20: =B6
A21: DIFERENCIA FINAL (debe ser 0) | B21: =B20-B19
A22: SALDO REAL EN FLEXXUS LUEGO DE IMPORTAR / POST-IMPORT SI APLICA | B22: =B7
A23: ACLARACIÓN: B17 es saldo ajustado conciliatorio, no saldo final real | B23: =B17
A25: Controles de consistencia interna
A26: Control | B26: Fórmula / Resultado esperado | C26: Estado
A27: B10 = suma hoja Flexxus no Banco PAV | B27: =B10-SUMIF('Flexxus no Banco'!D:D,"PAV",'Flexxus no Banco'!G:G) | C27: Debe dar 0
A28: B11 = suma hoja Flexxus no Banco egresos | B28: =B11-(SUM('Flexxus no Banco'!G:G)-B10) | C28: Debe dar 0
A29: B12 = suma hoja Banco ingresos no Flexxus | B29: =B12-SUM('Banco ingresos no Flexxus'!H:H) | C29: Debe dar 0
A30: B13 = suma hoja Banco egresos no Flexxus | B30: =B13-SUM('Banco egresos no Flexxus'!I:I) | C30: Debe dar 0
A31: B14 no es residual de cierre | B31: =B14 | C31: Debe dar 0
A32: B18 = total hoja Carga Flexxus | B32: =B18-'Carga Flexxus'!C5 | C32: Debe dar 0
A35: Detalle de diferencias por bloque
A36: Bloque | B36: Fecha | C36: Detalle / cuenta sugerida | D36: Cantidad | E36: Importe | F36: Observación
A37: Menos: INGRESOS registrados en FLEXXUS que NO están en el Banco | E37: =B10
A38: Flexxus ingreso no banco | B38: 21/04/2026 | C38: 2 PAV sin acreditar en banco | D38: 2 | E38: 107348.44 | F38: Detalle en hoja Flexxus no Banco
A39: Flexxus ingreso no banco | B39: 24/04/2026 | C39: 3 PAV sin acreditar en banco | D39: 3 | E39: 2980959 | F39: Detalle en hoja Flexxus no Banco
A40: Flexxus ingreso no banco | B40: 25/04/2026 | C40: 21 PAV sin acreditar en banco | D40: 21 | E40: 1127082.7 | F40: Detalle en hoja Flexxus no Banco
A41: Flexxus ingreso no banco | B41: 26/04/2026 | C41: 36 PAV sin acreditar en banco | D41: 36 | E41: 1555692.9 | F41: Detalle en hoja Flexxus no Banco
A42: Más: EGRESOS registrados en FLEXXUS que NO están en el Banco | E42: =B11
A43: Más: INGRESOS en el Banco pero NO registrados en FLEXXUS | E43: =B12
A44: Banco ingreso no Flexxus | C44: Ajuste menor redondeo/extracto | D44: 1 | E44: 3.62 | F44: Detalle en hoja Banco ingresos no Flexxus
A45: Banco ingreso no Flexxus | C45: QR / CR DEBIN SPOT | D45: 1 | E45: 32086.37 | F45: Detalle en hoja Banco ingresos no Flexxus
A46: Banco ingreso no Flexxus | C46: Transferencia entrante | D46: 1 | E46: 33180.87 | F46: Detalle en hoja Banco ingresos no Flexxus
...

Sheet Resumen banco
A1: Resumen banco no registrado en Flexxus - apertura para asientos
A2: Concepto banco | B2: Cuenta / apertura sugerida | C2: Tratamiento | D2: Cantidad | E2: Importe | F2: Bloque
A3: DEB LIQ MASTERCARD 24H | B3: Débito liquidación tarjeta | C3: Copiar en Flexxus: Tipo=MB-EXT | Movimiento=DEB LIQ MASTERCARD 24H | Monto=1.508,13 | D3: 9 | E3: 1508.13 | F3: Banco egreso no Flexxus
A4: DEBITO PAGO DIRECTO | B4: Débito pago directo | C4: Copiar en Flexxus: Tipo=MB-EXT | Movimiento=DEBITO PAGO DIRECTO | Monto=1.734.593,38 | D4: 1 | E4: 1734593.4 | F4: Banco egreso no Flexxus
A5: COM TRANSFE ELECTRONICA | B5: Gasto bancario / comisión | C5: Copiar en Flexxus: Tipo=MB-EXT | Movimiento=COM TRANSFE ELECTRONICA | Monto=2.868,00 | D5: 3 | E5: 2868 | F5: Banco egreso no Flexxus
A6: GRAVAMEN LEY 25413 S/CRED | B6: Anticipo Ganancias Ley 25.413 créditos | C6: Copiar en Flexxus: Tipo=MB-EXT | Movimiento=GRAVAMEN LEY 25.413 S/CRED | Monto=244.454,46 | D6: 347 | E6: 244454.46 | F6: Banco egreso no Flexxus
A7: GRAVAMEN LEY 25413 S/DEB | B7: Anticipo Ganancias Ley 25.413 débitos | C7: Copiar en Flexxus: Tipo=MB-EXT | Movimiento=GRAVAMEN LEY 25.413 S/DEB | Monto=106.472,89 | D7: 359 | E7: 106472.89 | F7: Banco egreso no Flexxus
A8: I.V.A. BASE | B8: IVA base / IVA sobre gastos | C8: Copiar en Flexxus: Tipo=MB-EXT | Movimiento=I.V.A. BASE | Monto=602,28 | D8: 3 | E8: 602.28 | F8: Banco egreso no Flexxus
A9: INGRESOS BRUTOS MENDOZA | B9: Retención Ingresos Brutos Mendoza | C9: Copiar en Flexxus: Tipo=MB-EXT | Movimiento=INGRESOS BRUTOS MENDOZA | Monto=407.424,17 | D9: 347 | E9: 407424.17 | F9: Banco egreso no Flexxus

Sheet Flexxus no Banco
A1: Detalle de movimientos registrados en Flexxus que no están acreditados en banco
A2: ID trazabilidad | B2: Estado trazabilidad | C2: Fecha Flexxus | D2: Tipo | E2: Número | F2: Movimiento | G2: Monto | H2: Local | I2: Cupón QR | J2: Número de Liquidación de Tarjeta | K2: Monto comparado | L2: Diferencia
A3: PEND-D3BF838B474C-A001 | B3: ABIERTO_NUEVO | C3: 21/04/2026 | D3: PAV | E3: 1800042763 | F3: PAGO TARJETA CREDITO | G3: 38886.97 | H3: Local 5 | I3: 1677 | K3: 38820.54 | L3: 66.43
A4: PEND-261C0F4C8AB8-A001 | B4: ABIERTO_NUEVO | C4: 21/04/2026 | D4: PAV | E4: 2300013968 | F4: PAGO TARJETA CREDITO | G4: 68461.47 | H4: Local 5 | J4: 341913 | K4: 69062.33 | L4: -600.86
A5: PEND-E0CE654F05FF-A001 | B5: ABIERTO_NUEVO | C5: 24/04/2026 | D5: PAV | E5: 2300014058 | F5: PAGO TARJETA CREDITO | G5: 32086.61 | H5: Local 1 | J5: 342462 | K5: 32183.44 | L5: -96.83
A6: PEND-6F07B64EC69E-A001 | B6: ABIERTO_NUEVO | C6: 24/04/2026 | D6: PAV | E6: 1800042817 | F6: PEDIDOS YA | G6: 2835183.6
A7: PEND-9E77A99A275C-A001 | B7: ABIERTO_NUEVO | C7: 24/04/2026 | D7: PAV | E7: 2200022628 | F7: PAGO TARJETA CREDITO | G7: 113688.74 | H7: Local 8 | J7: 342048 | K7: 114290.79 | L7: -602.05
A8: PEND-33F0F7058379-A001 | B8: ABIERTO_NUEVO | C8: 25/04/2026 | D8: PAV | E8: 2200022634 | F8: PAGO TARJETA CREDITO | G8: 149439.29 | H8: Local 7 | I8: 704 | K8: 149439.29 | L8: 0
A9: PEND-1249FE691999-A001 | B9: ABIERTO_NUEVO | C9: 25/04/2026 | D9: PAV | E9: 2100058091 | F9: PAGO TARJETA CREDITO | G9: 50605.35 | H9: Local 3 | J9: 341914 | K9: 49889.22 | L9: 716.13
A10: PEND-0694795B54BD-A001 | B10: ABIERTO_NUEVO | C10: 25/04/2026 | D10: PAV | E10: 1700036959 | F10: PAGO TARJETA CREDITO | G10: 109330.83 | H10: Local 8 | J10: 340735 | K10: 111455.52 | L10: -2124.69
A11: PEND-9748194786D3-A001 | B11: ABIERTO_NUEVO | C11: 25/04/2026 | D11: PAV | E11: 1700036960 | F11: PAGO TARJETA CREDITO | G11: 33670.88 | H11: Local 7 | J11: 342028 | K11: 33650.77 | L11: 20.11
A12: PEND-858043280EA1-A001 | B12: ABIERTO_NUEVO | C12: 25/04/2026 | D12: PAV | E12: 1900042953 | F12: PAGO TARJETA CREDITO | G12: 45950.85 | H12: Local 2 | J12: 342701 | K12: 45443.4 | L12: 507.45
A13: PEND-13D09F33D05A-A001 | B13: ABIERTO_NUEVO | C13: 25/04/2026 | D13: PAV | E13: 2200022644 | F13: PAGO TARJETA CREDITO | G13: 33175.72 | H13: Local 3 | J13: 341759 | K13: 32868.19 | L13: 307.53
A14: PEND-6058F1D1FE28-A001 | B14: ABIERTO_NUEVO | C14: 25/04/2026 | D14: PAV | E14: 2300014128 | F14: PAGO TARJETA CREDITO | G14: 52486.96 | H14: Local 7 | J14: 341765 | K14: 52184.78 | L14: 302.18
A15: PEND-71234A3ADAE8-A001 | B15: ABIERTO_NUEVO | C15: 25/04/2026 | D15: PAV | E15: 3400068554 | F15: PAGO TARJETA CREDITO | G15: 12279.97 | H15: Local 6 | J15: 342497 | K15: 12227.75 | L15: 52.22
A16: PEND-B73B971493F1-A001 | B16: ABIERTO_NUEVO | C16: 25/04/2026 | D16: PAV | E16: 3400068555 | F16: PAGO TARJETA CREDITO | G16: 13171.26 | H16: Local 2 | J16: 342038 | K16: 13205.97 | L16: -34.71
A17: PEND-6B486ECC4B99-A001 | B17: ABIERTO_NUEVO | C17: 25/04/2026 | D17: PAV | E17: 3400068556 | F17: PAGO TARJETA CREDITO | G17: 62687.26 | H17: Local 6 | I17: 3703 | K17: 62687.26 | L17: 0
A18: PEND-9DD41DA1C692-A001 | B18: ABIERTO_NUEVO | C18: 25/04/2026 | D18: PAV | E18: 2300014138 | F18: PAGO TARJETA CREDITO | G18: 75561.42 | H18: Local 8 | I18: 1330 | K18: 75561.42 | L18: 0
A19: PEND-AE5BB3AB0523-A001 | B19: ABIERTO_NUEVO | C19: 25/04/2026 | D19: PAV | E19: 2300014139 | F19: PAGO TARJETA CREDITO | G19: 65955.31 | H19: Local 2 | J19: 341912 | K19: 65540.74 | L19: 414.57
A20: PEND-FFA1C4B74821-A001 | B20: ABIERTO_NUEVO | C20: 25/04/2026 | D20: PAV | E20: 2300014140 | F20: PAGO TARJETA CREDITO | G20: 57834.69 | H20: Local 3 | J20: 342827 | K20: 58384.89 | L20: -550.2
A21: PEND-8886F49FCAB5-A001 | B21: ABIERTO_NUEVO | C21: 25/04/2026 | D21: PAV | E21: 2300014141 | F21: PAGO TARJETA CREDITO | G21: 31541.69 | H21: Local 3 | J21: 341775 | K21: 31694.33 | L21: -152.64
A22: PEND-86348EE2ACE2-A001 | B22: ABIERTO_NUEVO | C22: 25/04/2026 | D22: PAV | E22: 2300014142 | F22: PAGO TARJETA CREDITO | G22: 63083.38 | H22: Local 2 | J22: 342119 | K22: 64073.41 | L22: -990.03
A23: PEND-BB100ACD8AD2-A001 | B23: ABIERTO_NUEVO | C23: 25/04/2026 | D23: PAV | E23: 1700036970 | F23: PAGO TARJETA CREDITO | G23: 9804.17 | H23: Local 5 | I23: 1419 | K23: 9804.17 | L23: 0
A24: PEND-E481D4F49189-A001 | B24: ABIERTO_NUEVO | C24: 25/04/2026 | D24: PAV | E24: 1800042859 | F24: PAGO TARJETA CREDITO | G24: 9408.04 | H24: Local 5 | I24: 1668 | K24: 9408.04 | L24: 0
A25: PEND-054422237AA2-A001 | B25: ABIERTO_NUEVO | C25: 25/04/2026 | D25: PAV | E25: 3400068572 | F25: PAGO TARJETA CREDITO | G25: 10497.39 | H25: Local 6 | I25: 3710 | K25: 10497.39 | L25: 0
A26: PEND-E3352EB2DA7C-A001 | B26: ABIERTO_NUEVO | C26: 25/04/2026 | D26: PAV | E26: 2300014155 | F26: PAGO TARJETA CREDITO | G26: 121413.23 | H26: Local 8 | J26: 342839 | K26: 121314.12 | L26: 99.11
A27: PEND-8B96A8F68434-A001 | B27: ABIERTO_NUEVO | C27: 25/04/2026 | D27: PAV | E27: 3400068582 | F27: PAGO TARJETA CREDITO | G27: 12577.06 | H27: Local 2 | J27: 342289 | K27: 12348.75 | L27: 228.31
A28: PEND-36EF0AB72CF4-A001 | B28: ABIERTO_NUEVO | C28: 25/04/2026 | D28: PAV | E28: 2200022650 | F28: PAGO TARJETA CREDITO | G28: 106607.95 | H28: Local 2 | J28: 342413 | K28: 104519.82 | L28: 2088.13
A29: PEND-D12018A4F0FA-A001 | B29: ABIERTO_NUEVO | C29: 26/04/2026 | D29: PAV | E29: 2100058108 | F29: PAGO TARJETA CREDITO | G29: 78037.32 | H29: Local 5 | I29: 383 | K29: 78037.22 | L29: 0.1
A30: PEND-05F4B02153A9-A001 | B30: ABIERTO_NUEVO | C30: 26/04/2026 | D30: PAV | E30: 2200022661 | F30: PAGO TARJETA CREDITO | G30: 72887.55 | H30: Local 7 | J30: 340880 | K30: 71899.17 | L30: 988.38
A31: PEND-F7930F01B58E-A001 | B31: ABIERTO_NUEVO | C31: 26/04/2026 | D31: PAV | E31: 2200022660 | F31: PAGO TARJETA CREDITO | G31: 84375.26 | H31: Local 7 | J31: 342278 | K31: 83624.69 | L31: 750.57
A32: PEND-55E1645872E5-A001 | B32: ABIERTO_NUEVO | C32: 26/04/2026 | D32: PAV | E32: 2100058111 | F32: PAGO TARJETA CREDITO | G32: 25550.26 | H32: Local 5 | I32: 384 | K32: 25550.26 | L32: 0
A33: PEND-AB01F26DE461-A001 | B33: ABIERTO_NUEVO | C33: 26/04/2026 | D33: PAV | E33: 2100058122 | F33: PAGO TARJETA CREDITO | G33: 4456.44 | H33: Local 5 | I33: 386 | K33: 4456.44 | L33: 0
A34: PEND-13C2884393FE-A001 | B34: ABIERTO_NUEVO | C34: 26/04/2026 | D34: PAV | E34: 2100058129 | F34: PAGO TARJETA CREDITO | G34: 51298.58 | H34: Local 7 | J34: 341765 | K34: 52184.78 | L34: -886.2
A35: PEND-9764DD199D27-A001 | B35: ABIERTO_NUEVO | C35: 26/04/2026 | D35: PAV | E35: 2300014179 | F35: PAGO TARJETA CREDITO | G35: 94080.4 | H35: Local 8 | J35: 341766 | K35: 95474.32 | L35: -1393.92
A36: PEND-F9DF13E1D9E0-A001 | B36: ABIERTO_NUEVO | C36: 26/04/2026 | D36: PAV | E36: 1700036996 | F36: PAGO TARJETA CREDITO | G36: 16637.38 | H36: Local 5 | I36: 1422 | K36: 16637.38 | L36: 0
A37: PEND-2073512ACB55-A001 | B37: ABIERTO_NUEVO | C37: 26/04/2026 | D37: PAV | E37: 1700036997 | F37: PAGO TARJETA CREDITO | G37: 13368.35 | H37: Local 2 | J37: 342038 | K37: 13205.97 | L37: 162.38
A38: PEND-381263096B06-A001 | B38: ABIERTO_NUEVO | C38: 26/04/2026 | D38: PAV | E38: 1700036998 | F38: PAGO TARJETA CREDITO | G38: 24559.94 | H38: Local 5 | J38: 342703 | K38: 24697.5 | L38: -137.56
A39: PEND-51E4FE9CCA4D-A001 | B39: ABIERTO_NUEVO | C39: 26/04/2026 | D39: PAV | E39: 2100058148 | F39: PAGO TARJETA CREDITO | G39: 54962.76 | H39: Local 5 | I39: 393 | K39: 54962.76 | L39: 0
A40: PEND-4C001F8A1279-A001 | B40: ABIERTO_NUEVO | C40: 26/04/2026 | D40: PAV | E40: 2100058151 | F40: PAGO TARJETA CREDITO | G40: 12379 | H40: Local 2 | J40: 342289 | K40: 12348.75 | L40: 30.25
...

Sheet Banco ingresos no Flexxus
A1: Detalle de ingresos del banco no registrados en Flexxus - con diagnóstico de origen
A2: ID trazabilidad | B2: Estado trazabilidad | C2: Bloque | D2: Fecha banco | E2: Comprobante banco | F2: Concepto banco | G2: Categoría | H2: Importe | I2: Saldo banco | J2: Origen detectado | K2: Archivo donde aparece | L2: Local | M2: Cupón QR | N2: Número de Liquidación de Tarjeta | O2: Monto comparado | P2: Diferencia | Q2: Diagnóstico | R2: Acción sugerida
A3: PEND-C083FE6825F3-A001 | B3: ABIERTO_NUEVO | C3: Banco ingreso no Flexxus | D3: 24/04/2026 | E3: 3027923 | F3: C BE TR O/BCO-DIS TIT IBK - CUIT/CUIL: 30685376349 | G3: Transferencia entrante | H3: 33180.87 | J3: Transferencia entrante | K3: Corriente actual | Banco | L3: No identificado | O3: — | Q3: Transferencia entrante sin local detectado | R3: URGENTE: identificar local/origen antes de cerrar rutina administrativa
A4: PEND-73ABCD597425-A001 | B4: ABIERTO_NUEVO | C4: Banco ingreso no Flexxus | D4: 24/04/2026 | E4: 108559 | F4: CR DEBIN SPOT - CUIT/CUIL: 30711424179 | G4: QR / CR DEBIN SPOT | H4: 32086.37 | J4: QR / CR DEBIN SPOT | K4: Corriente actual | Banco | L4: No identificado | M4: No encontrado en QR | O4: — | Q4: QR bancario sin match QR PCT/local | R4: URGENTE: identificar local/origen antes de cerrar rutina administrativa
A5: PEND-F6CE22F10A4E-A001 | B5: CONTROL_CONTINUIDAD_MENOR | C5: Banco ingreso no Flexxus | D5: 24/04/2026 | E5: CTRL-CONTINUIDAD | F5: Diferencia técnica menor de continuidad/extracto bancario | G5: Ajuste menor redondeo/extracto | H5: 3.62 | J5: Ajuste menor redondeo/extracto | K5: Control de cobertura | Banco | L5: No identificado | O5: — | Q5: Origen/local no identificado | R5: URGENTE: identificar local/origen antes de cerrar rutina administrativa

Sheet Banco egresos no Flexxus
A1: Detalle de egresos del banco no registrados en Flexxus
A2: ID trazabilidad | B2: Estado trazabilidad | C2: Bloque | D2: Fecha banco | E2: Comprobante banco | F2: Concepto banco | G2: Cuenta / apertura sugerida | H2: Tratamiento | I2: Importe | J2: Saldo banco | K2: Acción
A3: PEND-93F12A4C2D02-A001 | B3: ABIERTO_NUEVO | C3: Banco egreso no Flexxus | D3: 24/04/2026 | E3: 108605 | F3: GRAVAMEN LEY 25413 S/DEB | G3: Anticipo Ganancias Ley 25.413 débitos | H3: Anticipo Impuesto a las Ganancias | I3: 4.3 | K3: Copiar en Flexxus: Tipo=MB-EXT | Movimiento=GRAVAMEN LEY 25.413 S/DEB | Monto=4,30 | Fecha: 24/04/2026
A4: PEND-6375F27720C1-A001 | B4: ABIERTO_NUEVO | C4: Banco egreso no Flexxus | D4: 24/04/2026 | E4: 108604 | F4: GRAVAMEN LEY 25413 S/DEB | G4: Anticipo Ganancias Ley 25.413 débitos | H4: Anticipo Impuesto a las Ganancias | I4: 0.63 | K4: Copiar en Flexxus: Tipo=MB-EXT | Movimiento=GRAVAMEN LEY 25.413 S/DEB | Monto=0,63 | Fecha: 24/04/2026
A5: PEND-829CA441D2C1-A001 | B5: ABIERTO_NUEVO | C5: Banco egreso no Flexxus | D5: 24/04/2026 | E5: 108603 | F5: GRAVAMEN LEY 25413 S/DEB | G5: Anticipo Ganancias Ley 25.413 débitos | H5: Anticipo Impuesto a las Ganancias | I5: 4.05 | K5: Copiar en Flexxus: Tipo=MB-EXT | Movimiento=GRAVAMEN LEY 25.413 S/DEB | Monto=4,05 | Fecha: 24/04/2026
A6: PEND-A03480487866-A001 | B6: ABIERTO_NUEVO | C6: Banco egreso no Flexxus | D6: 24/04/2026 | E6: 108602 | F6: GRAVAMEN LEY 25413 S/DEB | G6: Anticipo Ganancias Ley 25.413 débitos | H6: Anticipo Impuesto a las Ganancias | I6: 0.46 | K6: Copiar en Flexxus: Tipo=MB-EXT | Movimiento=GRAVAMEN LEY 25.413 S/DEB | Monto=0,46 | Fecha: 24/04/2026
A7: PEND-73A5D3E4D0C3-A001 | B7: ABIERTO_NUEVO | C7: Banco egreso no Flexxus | D7: 24/04/2026 | E7: 108601 | F7: GRAVAMEN LEY 25413 S/DEB | G7: Anticipo Ganancias Ley 25.413 débitos | H7: Anticipo Impuesto a las Ganancias | I7: 0.27 | K7: Copiar en Flexxus: Tipo=MB-EXT | Movimiento=GRAVAMEN LEY 25.413 S/DEB | Monto=0,27 | Fecha: 24/04/2026
A8: PEND-9E3B1F59512D-A001 | B8: ABIERTO_NUEVO | C8: Banco egreso no Flexxus | D8: 24/04/2026 | E8: 108600 | F8: GRAVAMEN LEY 25413 S/DEB | G8: Anticipo Ganancias Ley 25.413 débitos | H8: Anticipo Impuesto a las Ganancias | I8: 0.46 | K8: Copiar en Flexxus: Tipo=MB-EXT | Movimiento=GRAVAMEN LEY 25.413 S/DEB | Monto=0,46 | Fecha: 24/04/2026
A9: PEND-C862E82C3FFF-A001 | B9: ABIERTO_NUEVO | C9: Banco egreso no Flexxus | D9: 24/04/2026 | E9: 108599 | F9: GRAVAMEN LEY 25413 S/DEB | G9: Anticipo Ganancias Ley 25.413 débitos | H9: Anticipo Impuesto a las Ganancias | I9: 1.33 | K9: Copiar en Flexxus: Tipo=MB-EXT | Movimiento=GRAVAMEN LEY 25.413 S/DEB | Monto=1,33 | Fecha: 24/04/2026
A10: PEND-B9BAABFC9A1D-A001 | B10: ABIERTO_NUEVO | C10: Banco egreso no Flexxus | D10: 24/04/2026 | E10: 108598 | F10: GRAVAMEN LEY 25413 S/DEB | G10: Anticipo Ganancias Ley 25.413 débitos | H10: Anticipo Impuesto a las Ganancias | I10: 2.85 | K10: Copiar en Flexxus: Tipo=MB-EXT | Movimiento=GRAVAMEN LEY 25.413 S/DEB | Monto=2,85 | Fecha: 24/04/2026
A11: PEND-F58EC419CBE7-A001 | B11: ABIERTO_NUEVO | C11: Banco egreso no Flexxus | D11: 24/04/2026 | E11: 108597 | F11: GRAVAMEN LEY 25413 S/DEB | G11: Anticipo Ganancias Ley 25.413 débitos | H11: Anticipo Impuesto a las Ganancias | I11: 9 | K11: Copiar en Flexxus: Tipo=MB-EXT | Movimiento=GRAVAMEN LEY 25.413 S/DEB | Monto=9,00 | Fecha: 24/04/2026
A12: PEND-B67316409DEB-A001 | B12: ABIERTO_NUEVO | C12: Banco egreso no Flexxus | D12: 24/04/2026 | E12: 108596 | F12: GRAVAMEN LEY 25413 S/DEB | G12: Anticipo Ganancias Ley 25.413 débitos | H12: Anticipo Impuesto a las Ganancias | I12: 0.68 | K12: Copiar en Flexxus: Tipo=MB-EXT | Movimiento=GRAVAMEN LEY 25.413 S/DEB | Monto=0,68 | Fecha: 24/04/2026
A13: PEND-4D2FC872E3F5-A001 | B13: ABIERTO_NUEVO | C13: Banco egreso no Flexxus | D13: 24/04/2026 | E13: 108595 | F13: GRAVAMEN LEY 25413 S/DEB | G13: Anticipo Ganancias Ley 25.413 débitos | H13: Anticipo Impuesto a las Ganancias | I13: 0.94 | K13: Copiar en Flexxus: Tipo=MB-EXT | Movimiento=GRAVAMEN LEY 25.413 S/DEB | Monto=0,94 | Fecha: 24/04/2026
A14: PEND-E06B81872B01-A001 | B14: ABIERTO_NUEVO | C14: Banco egreso no Flexxus | D14: 24/04/2026 | E14: 108594 | F14: GRAVAMEN LEY 25413 S/DEB | G14: Anticipo Ganancias Ley 25.413 débitos | H14: Anticipo Impuesto a las Ganancias | I14: 0.77 | K14: Copiar en Flexxus: Tipo=MB-EXT | Movimiento=GRAVAMEN LEY 25.413 S/DEB | Monto=0,77 | Fecha: 24/04/2026
... A1071: PEND-FBDAA2086489-A001 | B1071: ABIERTO_NUEVO | C1071: Banco egreso no Flexxus | D1071: 20/04/2026 | E1071: 29841705 | F1071: DEB LIQ MASTERCARD 24H | G1071: Débito liquidación tarjeta | H1071: Revisar según concepto | I1071: 25.27 | K1071: Copiar en Flexxus: Tipo=MB-EXT | Movimiento=DEB LIQ MASTERCARD 24H | Monto=25,27 | Fecha: 20/04/2026

Sheet Regularizaciones
A1: Regularizaciones y ajustes ya incorporados
A2: ID trazabilidad | B2: Concepto | C2: Fecha Flexxus | D2: Tipo | E2: Número | F2: Movimiento | G2: Cant. banco | H2: Importe | I2: Observación
A3: AGREGADO-PAVQR | B3: PAV QR agregado contra banco | C3: 20/04/2026 | D3: PAV | E3: 1600010644 | F3: PAGO TARJETA CREDITO | G3: 104 | H3: 4376172.1 | I3: OK agregado PAV/QR

Sheet Carga Flexxus
A1: Movimientos para archivo de importación Flexxus
A2: PAV | B2: 242 | C2: 40677140
A3: MB-ENT-EX | B3: 8 | C3: 50600000
A4: MB-EXT | B4: 0 | C4: 0
A5: TOTAL | B5: 250 | C5: 91277140
A6: Fecha mov. Flexxus | B6: Tipo | C6: Nro. Flexxus | D6: Monto | E6: Fecha banco real | F6: Fecha acreditación a importar | G6: Concepto banco | H6: Comprobante banco | I6: Ajuste fecha
A7: 18/04/2026 | B7: MB-ENT-EX | C7: 0000-00026285 | D7: 15000000 | E7: 20/04/2026 | F7: 20/04/2026 | G7: DEB.TRAN.INTERBMISMO TIT | H7: 107338 | I7: No
A8: 19/04/2026 | B8: MB-ENT-EX | C8: 0000-00026442 | D8: 9000000 | E8: 20/04/2026 | F8: 20/04/2026 | G8: DB CREDIN TRANSFERENCIA | H8: 107465 | I8: No
A9: 19/04/2026 | B9: MB-ENT-EX | C9: 0000-00026443 | D9: 2000000 | E9: 20/04/2026 | F9: 20/04/2026 | G9: DB CREDIN TRANSFERENCIA | H9: 107466 | I9: No
A10: 20/04/2026 | B10: MB-ENT-EX | C10: 0000-00026447 | D10: 2000000 | E10: 20/04/2026 | F10: 20/04/2026 | G10: DB CREDIN TRANSFERENCIA | H10: 107467 | I10: No
A11: 20/04/2026 | B11: PAV | C11: 2300013922 | D11: 16835.44 | E11: 20/04/2026 | F11: 20/04/2026 | G11: CR DEBIN SPOT - CUIT/CUIL: 30711424179 | H11: 107468 | I11: No
A12: 20/04/2026 | B12: PAV | C12: 2300013925 | D12: 17924.79 | E12: 20/04/2026 | F12: 20/04/2026 | G12: CR DEBIN SPOT - CUIT/CUIL: 30711424179 | H12: 107469 | I12: No
A13: 20/04/2026 | B13: PAV | C13: 3400068386 | D13: 103729.5 | E13: 20/04/2026 | F13: 20/04/2026 | G13: CR LIQ MASTER DEB 24H | H13: 29841705 | I13: No
A14: 20/04/2026 | B14: PAV | C14: 3400068388 | D14: 35215.92 | E14: 20/04/2026 | F14: 20/04/2026 | G14: CR LIQ MASTERCARD 24H | H14: 29841705 | I14: No
A15: 20/04/2026 | B15: PAV | C15: 2100058007 | D15: 11388.68 | E15: 20/04/2026 | F15: 20/04/2026 | G15: CR DEBIN SPOT - CUIT/CUIL: 30711424179 | H15: 107431 | I15: No
A16: 20/04/2026 | B16: PAV | C16: 2100058008 | D16: 22777.36 | E16: 20/04/2026 | F16: 20/04/2026 | G16: CR DEBIN SPOT - CUIT/CUIL: 30711424179 | H16: 107438 | I16: No
A17: 20/04/2026 | B17: PAV | C17: 2300013929 | D17: 24956.06 | E17: 20/04/2026 | F17: 20/04/2026 | G17: CR DEBIN SPOT - CUIT/CUIL: 30711424179 | H17: 107473 | I17: No
A18: 20/04/2026 | B18: PAV | C18: 2300013930 | D18: 155396.67 | E18: 20/04/2026 | F18: 20/04/2026 | G18: CR LIQ MASTER DEB 24H | H18: 32032899 | I18: No
... A256: 26/04/2026 | B256: PAV | C256: 3400068655 | D256: 11388.68 | E256: 20/04/2026 | F256: 26/04/2026 | G256: CR DEBIN SPOT - CUIT/CUIL: 30711424179 | H256: 107366 | I256: Sí

Sheet Auditoría QR PCT
A1: Fecha QR | B1: Estado | C1: Comercio | D1: Local | E1: Terminal | F1: Cupón/ID | G1: Monto Bruto | H1: Neto Calc. | I1: En Banco | J1: En Flexxus | K1: Estado Match
A2: 26/04/2026 | B2: Completa | C2: 29841705 | D2: Local 6 | E2: 69333384 | F2: 3737 | G2: 24600 | H2: 24361.87 | I2: Sí | J2: Sí | K2: OK - en banco y Flexxus
A3: 26/04/2026 | B3: Completa | C3: 29841705 | D3: Local 6 | E3: 69333384 | F3: 3736 | G3: 11500 | H3: 11388.68 | I3: Sí | J3: Sí | K3: OK - en banco y Flexxus
A4: 26/04/2026 | B4: Completa | C4: 32032899 | D4: Local 8 | E4: 69443515 | F4: 1354 | G4: 60600 | H4: 60013.39 | I4: No | J4: No | K4: Revisar
A5: 26/04/2026 | B5: Completa | C5: 32032899 | D5: Local 8 | E5: 69443515 | F5: 1352 | G5: 58200 | H5: 57636.62 | I5: No | J5: No | K5: Revisar
A6: 26/04/2026 | B6: Completa | C6: 29841705 | D6: Local 6 | E6: 69333384 | F6: 3735 | G6: 67700 | H6: 67044.66 | I6: No | J6: No | K6: Revisar
A7: 26/04/2026 | B7: Completa | C7: 29841670 | D7: Local 5 | E7: 69343173 | F7: 1694 | G7: 7700 | H7: 7625.46 | I7: Sí | J7: Sí | K7: OK - en banco y Flexxus
A8: 26/04/2026 | B8: Completa | C8: 29841705 | D8: Local 6 | E8: 69333384 | F8: 3734 | G8: 70200 | H8: 69520.46 | I8: No | J8: No | K8: Revisar
A9: 26/04/2026 | B9: Completa | C9: 29841670 | D9: Local 5 | E9: 69343173 | F9: 1692 | G9: 65200 | H9: 64568.86 | I9: No | J9: No | K9: Revisar
A10: 26/04/2026 | B10: Completa | C10: 29841670 | D10: Local 5 | E10: 69343173 | F10: 1691 | G10: 34800 | H10: 34463.14 | I10: No | J10: No | K10: Revisar
A11: 26/04/2026 | B11: Completa | C11: 29841670 | D11: Local 5 | E11: 69467539 | F11: 397 | G11: 27000 | H11: 26738.64 | I11: Sí | J11: Sí | K11: OK - en banco y Flexxus
A12: 26/04/2026 | B12: Completa | C12: 29841705 | D12: Local 6 | E12: 69333384 | F12: 3733 | G12: 27100 | H12: 26837.67 | I12: No | J12: No | K12: Revisar
A13: 26/04/2026 | B13: Completa | C13: 29841705 | D13: Local 6 | E13: 69333384 | F13: 3732 | G13: 39100 | H13: 38721.51 | I13: No | J13: No | K13: Revisar
... A157: 20/04/2026 | B157: Completa | C157: 32032899 | D157: Local 8 | E157: 69443515 | F157: 1287 | G157: 17000 | H157: 16835.44 | I157: Sí | J157: Sí | K157: OK - en banco y Flexxus

Sheet Auditoría TRX Merchant
A1: Fecha Pago | B1: Nro Liquidación | C1: Comercio | D1: Local | E1: Tarjeta | F1: Monto Neto | G1: Matcheado | H1: Estado
A2: 20/04/2026 | B2: 342289 | C2: 29841627 | D2: Local 2 | E2: Mastercard Debit | F2: 12348.75 | G2: Sí | H2: OK
A3: 20/04/2026 | B3: 342312 | C3: 29841627 | D3: Local 2 | E3: Visa Débito | F3: 11360.85 | G3: Sí | H3: OK
A4: 20/04/2026 | B4: 341773 | C4: 29841642 | D4: Local 1 | E4: Visa Crédito | F4: 14184.19 | G4: Sí | H4: OK
A5: 20/04/2026 | B5: 342313 | C5: 29841642 | D5: Local 1 | E5: Visa Débito | F5: 49681.49 | G5: Sí | H5: OK
A6: 20/04/2026 | B6: 341774 | C6: 29841670 | D6: Local 5 | E6: Visa Crédito | F6: 8217.05 | G6: Sí | H6: OK
A7: 20/04/2026 | B7: 342314 | C7: 29841670 | D7: Local 5 | E7: Visa Débito | F7: 98790 | G7: Sí | H7: OK
A8: 20/04/2026 | B8: 341759 | C8: 29841683 | D8: Local 3 | E8: Mastercard Crédito | F8: 32868.19 | G8: Sí | H8: OK
A9: 20/04/2026 | B9: 341775 | C9: 29841683 | D9: Local 3 | E9: Visa Crédito | F9: 31694.33 | G9: Sí | H9: OK
A10: 20/04/2026 | B10: 342315 | C10: 29841683 | D10: Local 3 | E10: Visa Débito | F10: 301218 | G10: Sí | H10: OK
A11: 20/04/2026 | B11: 341760 | C11: 29841705 | D11: Local 6 | E11: Mastercard Crédito | F11: 35215.92 | G11: Sí | H11: OK
A12: 20/04/2026 | B12: 342224 | C12: 29841705 | D12: Local 6 | E12: Mastercard Crédito | F12: -25.27 | G12: No | H12: Revisar
A13: 20/04/2026 | B13: 342316 | C13: 29841705 | D13: Local 6 | E13: Visa Débito | F13: 103729.5 | G13: Sí | H13: OK
... A145: 24/04/2026 | B145: 342853 | C145: 32032899 | D145: Local 8 | E145: Mastercard Crédito | F145: 41672.17 | G145: Sí | H145: OK

Sheet Resumen atraso por local
A1: Resumen de atraso/carga pendiente por local
A2: Este tablero no sanciona por timing bancario normal; marca pendientes atribuibles o no identificados para seguimiento operativo.
A4: Local | B4: Cantidad pendientes | C4: Importe total observado | D4: Banco ingresos no Flexxus | E4: Flexxus no Banco | F4: Banco egresos no Flexxus | G4: Categoría dominante | H4: Severidad | I4: Comunicado sugerido
A5: Administración/Banco | B5: 1069 | C5: 2497923.3 | D5: 0 | E5: 0 | F5: 2497923.3 | G5: Anticipo Ganancias Ley 25.413 débitos | H5: ALTA | I5: Administración/Banco: revisar egresos/impuestos/gastos pendientes de registro.
A6: Local 1 | B6: 4 | C6: 172414.95 | D6: 0 | E6: 172414.95 | F6: 0 | G6: PAV | H6: MEDIA | I6: Local 1: verificar PAV/ventas cargadas en Flexxus pendientes de acreditación bancaria.
A7: Local 2 | B7: 10 | C7: 424499.69 | D7: 0 | E7: 424499.69 | F7: 0 | G7: PAV | H7: ALTA | I7: Local 2: verificar PAV/ventas cargadas en Flexxus pendientes de acreditación bancaria.
A8: Local 3 | B8: 6 | C8: 290807.46 | D8: 0 | E8: 290807.46 | F8: 0 | G8: PAV | H8: MEDIA | I8: Local 3: verificar PAV/ventas cargadas en Flexxus pendientes de acreditación bancaria.
A9: Local 5 | B9: 19 | C9: 678763.2 | D9: 0 | E9: 678763.2 | F9: 0 | G9: PAV | H9: ALTA | I9: Local 5: verificar PAV/ventas cargadas en Flexxus pendientes de acreditación bancaria.
A10: Local 6 | B10: 10 | C10: 341264.4 | D10: 0 | E10: 341264.4 | F10: 0 | G10: PAV | H10: ALTA | I10: Local 6: verificar PAV/ventas cargadas en Flexxus pendientes de acreditación bancaria.
A11: Local 7 | B11: 7 | C11: 514075.11 | D11: 0 | E11: 514075.11 | F11: 0 | G11: PAV | H11: MEDIA | I11: Local 7: verificar PAV/ventas cargadas en Flexxus pendientes de acreditación bancaria.
A12: Local 8 | B12: 5 | C12: 514074.62 | D12: 0 | E12: 514074.62 | F12: 0 | G12: PAV | H12: MEDIA | I12: Local 8: verificar PAV/ventas cargadas en Flexxus pendientes de acreditación bancaria.
A13: No identificado | B13: 4 | C13: 2900454.5 | D13: 65270.86 | E13: 2835183.6 | F13: 0 | G13: Ajuste menor redondeo/extracto | H13: ALTA | I13: Identificar origen/local de movimientos bancarios no registrados antes del cierre.
A16: Detalle de hallazgos por local
A17: Local | B17: Bloque | C17: Categoría | D17: Importe | E17: Estado trazabilidad | F17: Origen detectado | G17: Acción sugerida
A18: Administración/Banco | B18: Banco egreso no Flexxus | C18: Anticipo Ganancias Ley 25.413 créditos | D18: 430.2 | E18: ABIERTO_NUEVO | F18: Banco / impuesto / gasto | G18: Copiar en Flexxus: Tipo=MB-EXT | Movimiento=GRAVAMEN LEY 25.413 S/CRED | Monto=430,20 | Fecha: 24/04/2026
A19: Administración/Banco | B19: Banco egreso no Flexxus | C19: Anticipo Ganancias Ley 25.413 créditos | D19: 62.98 | E19: ABIERTO_NUEVO | F19: Banco / impuesto / gasto | G19: Copiar en Flexxus: Tipo=MB-EXT | Movimiento=GRAVAMEN LEY 25.413 S/CRED | Monto=62,98 | Fecha: 24/04/2026
A20: Administración/Banco | B20: Banco egreso no Flexxus | C20: Anticipo Ganancias Ley 25.413 créditos | D20: 405.24 | E20: ABIERTO_NUEVO | F20: Banco / impuesto / gasto | G20: Copiar en Flexxus: Tipo=MB-EXT | Movimiento=GRAVAMEN LEY 25.413 S/CRED | Monto=405,24 | Fecha: 24/04/2026
A21: Administración/Banco | B21: Banco egreso no Flexxus | C21: Anticipo Ganancias Ley 25.413 créditos | D21: 45.75 | E21: ABIERTO_NUEVO | F21: Banco / impuesto / gasto | G21: Copiar en Flexxus: Tipo=MB-EXT | Movimiento=GRAVAMEN LEY 25.413 S/CRED | Monto=45,75 | Fecha: 24/04/2026
A22: Administración/Banco | B22: Banco egreso no Flexxus | C22: Anticipo Ganancias Ley 25.413 créditos | D22: 26.74 | E22: ABIERTO_NUEVO | F22: Banco / impuesto / gasto | G22: Copiar en Flexxus: Tipo=MB-EXT | Movimiento=GRAVAMEN LEY 25.413 S/CRED | Monto=26,74 | Fecha: 24/04/2026
A23: Administración/Banco | B23: Banco egreso no Flexxus | C23: Anticipo Ganancias Ley 25.413 créditos | D23: 46.35 | E23: ABIERTO_NUEVO | F23: Banco / impuesto / gasto | G23: Copiar en Flexxus: Tipo=MB-EXT | Movimiento=GRAVAMEN LEY 25.413 S/CRED | Monto=46,35 | Fecha: 24/04/2026
A24: Administración/Banco | B24: Banco egreso no Flexxus | C24: Anticipo Ganancias Ley 25.413 créditos | D24: 133.1 | E24: ABIERTO_NUEVO | F24: Banco / impuesto / gasto | G24: Copiar en Flexxus: Tipo=MB-EXT | Movimiento=GRAVAMEN LEY 25.413 S/CRED | Monto=133,10 | Fecha: 24/04/2026
A25: Administración/Banco | B25: Banco egreso no Flexxus | C25: Anticipo Ganancias Ley 25.413 créditos | D25: 285.21 | E25: ABIERTO_NUEVO | F25: Banco / impuesto / gasto | G25: Copiar en Flexxus: Tipo=MB-EXT | Movimiento=GRAVAMEN LEY 25.413 S/CRED | Monto=285,21 | Fecha: 24/04/2026
A26: Administración/Banco | B26: Banco egreso no Flexxus | C26: Anticipo Ganancias Ley 25.413 créditos | D26: 900 | E26: ABIERTO_NUEVO | F26: Banco / impuesto / gasto | G26: Copiar en Flexxus: Tipo=MB-EXT | Movimiento=GRAVAMEN LEY 25.413 S/CRED | Monto=900,00 | Fecha: 24/04/2026
A27: Administración/Banco | B27: Banco egreso no Flexxus | C27: Anticipo Ganancias Ley 25.413 créditos | D27: 68.33 | E27: ABIERTO_NUEVO | F27: Banco / impuesto / gasto | G27: Copiar en Flexxus: Tipo=MB-EXT | Movimiento=GRAVAMEN LEY 25.413 S/CRED | Monto=68,33 | Fecha: 24/04/2026
A28: Administración/Banco | B28: Banco egreso no Flexxus | C28: Anticipo Ganancias Ley 25.413 créditos | D28: 94.48 | E28: ABIERTO_NUEVO | F28: Banco / impuesto / gasto | G28: Copiar en Flexxus: Tipo=MB-EXT | Movimiento=GRAVAMEN LEY 25.413 S/CRED | Monto=94,48 | Fecha: 24/04/2026
A29: Administración/Banco | B29: Banco egreso no Flexxus | C29: Anticipo Ganancias Ley 25.413 créditos | D29: 77.19 | E29: ABIERTO_NUEVO | F29: Banco / impuesto / gasto | G29: Copiar en Flexxus: Tipo=MB-EXT | Movimiento=GRAVAMEN LEY 25.413 S/CRED | Monto=77,19 | Fecha: 24/04/2026
... A1151: No identificado | B1151: Flexxus no Banco | C1151: PAV | D1151: 2835183.6 | E1151: ABIERTO_NUEVO | F1151: Flexxus pendiente sin local detectado | G1151: Verificar acreditación bancaria o fecha de cierre

Sheet Control cobertura
A1: Control de cobertura total: ninguna línea puede quedar en zona muerta
A2: Fuente | B2: Control | C2: Total fuente | D2: Total clasificado | E2: Diferencia | F2: Estado | G2: Observación
A3: Banco | B3: Ingresos banco: real = conciliado + regularizado + Banco ingresos no Flexxus | C3: 40742407 | D3: 40742410 | E3: -3.62 | F3: ERROR | G3: Hay movimientos clasificados de forma incompleta; revisar detalle
A4: Banco | B4: Egresos banco: real = conciliado + regularizado + Banco egresos no Flexxus | C4: 53097923 | D4: 53097923 | E4: 0 | F4: OK | G4: Sin movimientos en zona muerta
A5: Flexxus | B5: PAV Flexxus: real = conciliado + regularizado + Flexxus no Banco | C5: 46448223 | D5: 46448223 | E5: 0 | F5: OK | G5: Sin movimientos en zona muerta
A6: Flexxus | B6: Egresos Flexxus: real = conciliado + regularizado + Flexxus egresos no Banco | C6: 50600000 | D6: 50600000 | E6: 0 | F6: OK | G6: Sin movimientos en zona muerta
A9: Movimientos bancarios pendientes visibles
A10: Fuente | B10: Fecha | C10: Comprobante/Número | D10: Concepto | E10: Importe | F10: Estado interno | G10: Diagnóstico
A11: Banco | B11: 24/04/2026 | C11: 108605 | D11: GRAVAMEN LEY 25413 S/DEB | E11: 4.3 | F11: Pendiente visible en hojas Banco no Flexxus
A12: Banco | B12: 24/04/2026 | C12: 108604 | D12: GRAVAMEN LEY 25413 S/DEB | E12: 0.63 | F12: Pendiente visible en hojas Banco no Flexxus
A13: Banco | B13: 24/04/2026 | C13: 108603 | D13: GRAVAMEN LEY 25413 S/DEB | E13: 4.05 | F13: Pendiente visible en hojas Banco no Flexxus
A14: Banco | B14: 24/04/2026 | C14: 108602 | D14: GRAVAMEN LEY 25413 S/DEB | E14: 0.46 | F14: Pendiente visible en hojas Banco no Flexxus
A15: Banco | B15: 24/04/2026 | C15: 108601 | D15: GRAVAMEN LEY 25413 S/DEB | E15: 0.27 | F15: Pendiente visible en hojas Banco no Flexxus
A16: Banco | B16: 24/04/2026 | C16: 108600 | D16: GRAVAMEN LEY 25413 S/DEB | E16: 0.46 | F16: Pendiente visible en hojas Banco no Flexxus
A17: Banco | B17: 24/04/2026 | C17: 108599 | D17: GRAVAMEN LEY 25413 S/DEB | E17: 1.33 | F17: Pendiente visible en hojas Banco no Flexxus
A18: Banco | B18: 24/04/2026 | C18: 108598 | D18: GRAVAMEN LEY 25413 S/DEB | E18: 2.85 | F18: Pendiente visible en hojas Banco no Flexxus
A19: Banco | B19: 24/04/2026 | C19: 108597 | D19: GRAVAMEN LEY 25413 S/DEB | E19: 9 | F19: Pendiente visible en hojas Banco no Flexxus
A20: Banco | B20: 24/04/2026 | C20: 108596 | D20: GRAVAMEN LEY 25413 S/DEB | E20: 0.68 | F20: Pendiente visible en hojas Banco no Flexxus
A21: Banco | B21: 24/04/2026 | C21: 108595 | D21: GRAVAMEN LEY 25413 S/DEB | E21: 0.94 | F21: Pendiente visible en hojas Banco no Flexxus
A22: Banco | B22: 24/04/2026 | C22: 108594 | D22: GRAVAMEN LEY 25413 S/DEB | E22: 0.77 | F22: Pendiente visible en hojas Banco no Flexxus
... A1081: Banco | B1081: 20/04/2026 | C1081: 29841705 | D1081: DEB LIQ MASTERCARD 24H | E1081: 25.27 | F1081: Pendiente visible en hojas Banco no Flexxus

Sheet Notas proceso
A1: Tema | B1: Detalle
A2: Regla base | B2: Conciliación de Flexxus define movimientos pendientes, tipo y fecha de movimiento. Banco confirma acreditación/débito real.
A3: Regla de carga | B3: Solo se carga en Flexxus si existe en banco. Merchant/QR se usa como auditoría auxiliar, no como base directa de carga.
A4: QR Banco Nación | B4: Todo CR DEBIN SPOT se considera QR/PAV.
A5: QR Merchant | B5: Neto QR = Monto total x 0,99032; se usa para identificar local y cupón cuando corresponde.
A6: Local | B6: Locales: 29841642=Local 1, 29841627=Local 2, 29841683=Local 3, 29841670=Local 5, 29841705=Local 6, 31995644=Local 7, 32032899=Local 8
A7: Pedidos Ya | B7: PEDIDOS YA es cliente/canal aparte, no tarjeta ni QR; no completar cupón QR ni liquidación.
A8: Fechas Flexxus | B8: Si fecha banco < fecha Flexxus, el archivo final usa FECHAACREDITACION = FECHAMOVIMIENTO; la fecha real queda en auditoría.
A9: V5.8 | B9: Versión final: separa saldo Flexxus real, saldo Flexxus ajustado para conciliación y total importado .xls; mantiene fórmulas reales y control de cobertura.
A10: V5.6 | B10: Separa pendientes reales abiertos de movimientos ya procesados/históricos en la pantalla principal y en el conteo del historial.
A11: V5.5 | B11: Corrige identificación de local/liquidación en Banco ingresos no Flexxus: usa TRX exacto, QR PCT y fallback por comprobante banco=código de comercio.
